2020-05-14 09:38:14,860 INFO: Microblog startup [in D:\flasktest\app\__init__.py:50]
2020-05-14 09:42:07,647 INFO: Microblog startup [in D:\flasktest\app\__init__.py:50]
2020-05-14 09:56:36,594 INFO: Microblog startup [in D:\flasktest\app\__init__.py:50]
2020-05-15 10:48:19,568 INFO: Microblog startup [in D:\flasktest\app\__init__.py:54]
2020-05-15 10:48:21,011 ERROR: Exception on /login [GET] [in D:\flasktest\venv\lib\site-packages\flask\app.py:1892]
Traceback (most recent call last):
  File "D:\flasktest\venv\lib\site-packages\flask\app.py", line 2447, in wsgi_app
    response = self.full_dispatch_request()
  File "D:\flasktest\venv\lib\site-packages\flask\app.py", line 1952, in full_dispatch_request
    rv = self.handle_user_exception(e)
  File "D:\flasktest\venv\lib\site-packages\flask\app.py", line 1821, in handle_user_exception
    reraise(exc_type, exc_value, tb)
  File "D:\flasktest\venv\lib\site-packages\flask\_compat.py", line 39, in reraise
    raise value
  File "D:\flasktest\venv\lib\site-packages\flask\app.py", line 1950, in full_dispatch_request
    rv = self.dispatch_request()
  File "D:\flasktest\venv\lib\site-packages\flask\app.py", line 1936, in dispatch_request
    return self.view_functions[rule.endpoint](**req.view_args)
  File "D:\flasktest\app\routes.py", line 59, in login
    return render_template('login.html', title='Sign In', form=form)
  File "D:\flasktest\venv\lib\site-packages\flask\templating.py", line 140, in render_template
    ctx.app,
  File "D:\flasktest\venv\lib\site-packages\flask\templating.py", line 120, in _render
    rv = template.render(context)
  File "D:\flasktest\venv\lib\site-packages\jinja2\environment.py", line 1090, in render
    self.environment.handle_exception()
  File "D:\flasktest\venv\lib\site-packages\jinja2\environment.py", line 832, in handle_exception
    reraise(*rewrite_traceback_stack(source=source))
  File "D:\flasktest\venv\lib\site-packages\jinja2\_compat.py", line 28, in reraise
    raise value.with_traceback(tb)
  File "D:\flasktest\app\templates\login.html", line 1, in top-level template code
    {% extends "base.html" %}
  File "D:\flasktest\app\templates\base.html", line 31, in top-level template code
    {% block content %}{% endblock %}
  File "D:\flasktest\app\templates\login.html", line 8, in block "content"
    <a href="{{ url_for('reset_password_request') }}">Click to Reset It</a>
  File "D:\flasktest\venv\lib\site-packages\flask\helpers.py", line 370, in url_for
    return appctx.app.handle_url_build_error(error, endpoint, values)
  File "D:\flasktest\venv\lib\site-packages\flask\app.py", line 2216, in handle_url_build_error
    reraise(exc_type, exc_value, tb)
  File "D:\flasktest\venv\lib\site-packages\flask\_compat.py", line 39, in reraise
    raise value
  File "D:\flasktest\venv\lib\site-packages\flask\helpers.py", line 358, in url_for
    endpoint, values, method=method, force_external=external
  File "D:\flasktest\venv\lib\site-packages\werkzeug\routing.py", line 2179, in build
    raise BuildError(endpoint, values, method, self)
werkzeug.routing.BuildError: Could not build url for endpoint 'reset_password_request'. Did you mean 'reset_password' instead?
2020-05-15 10:55:04,752 INFO: Microblog startup [in D:\flasktest\app\__init__.py:54]
2020-05-15 22:16:34,778 INFO: Microblog startup [in D:\flasktest\app\__init__.py:54]
2020-05-15 22:34:42,308 INFO: Microblog startup [in D:\flasktest\app\__init__.py:54]
2020-05-15 22:36:11,302 INFO: Microblog startup [in D:\flasktest\app\__init__.py:54]
2020-05-16 10:40:30,442 INFO: Microblog startup [in D:\flasktest\app\__init__.py:57]
2020-05-16 10:40:48,420 ERROR: Exception on /login [GET] [in D:\flasktest\venv\lib\site-packages\flask\app.py:1892]
Traceback (most recent call last):
  File "D:\flasktest\venv\lib\site-packages\flask\app.py", line 2447, in wsgi_app
    response = self.full_dispatch_request()
  File "D:\flasktest\venv\lib\site-packages\flask\app.py", line 1952, in full_dispatch_request
    rv = self.handle_user_exception(e)
  File "D:\flasktest\venv\lib\site-packages\flask\app.py", line 1821, in handle_user_exception
    reraise(exc_type, exc_value, tb)
  File "D:\flasktest\venv\lib\site-packages\flask\_compat.py", line 39, in reraise
    raise value
  File "D:\flasktest\venv\lib\site-packages\flask\app.py", line 1950, in full_dispatch_request
    rv = self.dispatch_request()
  File "D:\flasktest\venv\lib\site-packages\flask\app.py", line 1936, in dispatch_request
    return self.view_functions[rule.endpoint](**req.view_args)
  File "D:\flasktest\app\routes.py", line 59, in login
    return render_template('login.html', title='Sign In', form=form)
  File "D:\flasktest\venv\lib\site-packages\flask\templating.py", line 140, in render_template
    ctx.app,
  File "D:\flasktest\venv\lib\site-packages\flask\templating.py", line 120, in _render
    rv = template.render(context)
  File "D:\flasktest\venv\lib\site-packages\jinja2\environment.py", line 1090, in render
    self.environment.handle_exception()
  File "D:\flasktest\venv\lib\site-packages\jinja2\environment.py", line 832, in handle_exception
    reraise(*rewrite_traceback_stack(source=source))
  File "D:\flasktest\venv\lib\site-packages\jinja2\_compat.py", line 28, in reraise
    raise value.with_traceback(tb)
  File "D:\flasktest\app\templates\login.html", line 1, in top-level template code
    {% extends "base.html" %}
  File "D:\flasktest\app\templates\base.html", line 1, in top-level template code
    {% extends 'bootstrap/base.html' %}
  File "D:\flasktest\venv\lib\site-packages\flask_bootstrap\templates\bootstrap\base.html", line 1, in top-level template code
    {% block doc -%}
  File "D:\flasktest\venv\lib\site-packages\flask_bootstrap\templates\bootstrap\base.html", line 4, in block "doc"
    {%- block html %}
  File "D:\flasktest\venv\lib\site-packages\flask_bootstrap\templates\bootstrap\base.html", line 20, in block "html"
    {% block body -%}
  File "D:\flasktest\venv\lib\site-packages\flask_bootstrap\templates\bootstrap\base.html", line 21, in block "body"
    {% block navbar %}
  File "D:\flasktest\app\templates\base.html", line 17, in block "navbar"
    <a class="navbar-brand" href="{{ url_for('main.index') }}">Microblog</a>
  File "D:\flasktest\venv\lib\site-packages\flask\helpers.py", line 370, in url_for
    return appctx.app.handle_url_build_error(error, endpoint, values)
  File "D:\flasktest\venv\lib\site-packages\flask\app.py", line 2216, in handle_url_build_error
    reraise(exc_type, exc_value, tb)
  File "D:\flasktest\venv\lib\site-packages\flask\_compat.py", line 39, in reraise
    raise value
  File "D:\flasktest\venv\lib\site-packages\flask\helpers.py", line 358, in url_for
    endpoint, values, method=method, force_external=external
  File "D:\flasktest\venv\lib\site-packages\werkzeug\routing.py", line 2179, in build
    raise BuildError(endpoint, values, method, self)
werkzeug.routing.BuildError: Could not build url for endpoint 'main.index'. Did you mean 'index' instead?
